﻿﻿﻿﻿一旦引发了一个异常，此异常会在调用堆栈中传播，直到找到针对它的 catch 语句

如果引发异常之后没有在调用堆栈上找到兼容的 catch 块，则会出现以下三种情况之一：

- 如果异常存在于**终结器**内，将中止终结器，并调用基类终结器（如果有）。

```C#
终结器会对性能产生一定影响，所以一般用于释放非托管资源时
在终结器中抛出的异常可能会导致程序不稳定。如果在终结器中抛出异常，终结器会被中止，并且（若存在）会调用基类的终结器。因此，在终结器中应该尽量捕获并处理异常
终结器不能保证在对象不再使用时立即执行，它的执行时间是不确定的。如果需要确定性地释放资源，建议实现 IDisposable 接口，并使用 using 语句或显式调用 Dispose 方法。
终结器就是 类名前面加~ 
 ~MyClass()
    {
        try
        {
            // 模拟可能抛出异常的操作
            throw new Exception("Exception in finalizer");
        }
        catch (Exception ex)
        {
            // 异常被捕获，终结器继续执行清理操作
            // 但如果不捕获，终结器会被中止
        }
    }
```
- 如果调用堆栈包含静态构造函数或静态字段初始值设定项，将引发 TypeInitializationException，同时将原始异常分配给新异常的 InnerException 属性。:

		(TypeInitializationException，InnerException 特定的异常可以帮我们快速定位问题)
- 如果到达线程的开头，则终止线程：

    ```C#
	       (新线程的起始处抛出了异常，线程会被终止。需要注意的是，主线程无法直接捕获新线程内部的异常，所以在线程代码中要做好异常处理)
		     Thread newThread = new Thread(() =>
            {
                // 模拟线程起始处抛出异常
                throw new Exception("Exception at the start of the thread");
            });
    
            try
            {
                newThread.Start();
                newThread.Join();
            }
            catch (Exception ex)
            {
                // 这里捕获不到线程内部的异常
                Console.WriteLine($"Caught exception: {ex.Message}");
            }
    
    ```


### 注意

- 不要使用异常在正常执行过程中更改程序的流。 使用异常来报告和处理错误条件。
- 只能引发异常，而不能作为返回值或参数返回异常。
- 请勿有意从自己的源代码中引发 System.Exception、System.SystemException、System.NullReferenceException 或 System.IndexOutOfRangeException。
- 不要创建可在调试模式下引发，但不会在发布模式下引发的异常。 若要在开发阶段确定运行时错误，请改用调试断言。(Debug.Assert(!invalidCondition, "Invalid condition detected"); )

        特性	调试模式 (DEBUG 定义)	发布模式 (DEBUG 未定义)
        throw + #if DEBUG	异常会中断程序流	代码不存在，错误被静默忽略
        Debug.Assert	触发断言失败（弹窗/日志）	代码自动移除，无性能损耗
        异常处理机制	强制开发者立即修复问题	隐藏错误，导致生产环境不稳定


### 异步方法里的异常
    使用 async 修饰符声明的方法在出现异常时，有一些特殊的注意事项。 方法 async 中引发的异常会存储在返回的任务中，直到任务即将出现时才会出现

![image-20250429134425120](https://cdn.jsdelivr.net/gh/humoyun1798/image/image/imagessimage-20250429134425120.png)





### 编译器异常类列表

| 异常                                                         | 描述                                                         |
| :----------------------------------------------------------- | :----------------------------------------------------------- |
| [ArithmeticException](https://learn.microsoft.com/zh-cn/dotnet/api/system.arithmeticexception) | 算术运算期间出现的异常的基类，例如 [DivideByZeroException](https://learn.microsoft.com/zh-cn/dotnet/api/system.dividebyzeroexception) 和 [OverflowException](https://learn.microsoft.com/zh-cn/dotnet/api/system.overflowexception)。 |
| [ArrayTypeMismatchException](https://learn.microsoft.com/zh-cn/dotnet/api/system.arraytypemismatchexception) | 由于元素的实际类型与数组的实际类型不兼容而导致数组无法存储给定元素时引发。 |
| [DivideByZeroException](https://learn.microsoft.com/zh-cn/dotnet/api/system.dividebyzeroexception) | 尝试将整数值除以零时引发。                                   |
| [IndexOutOfRangeException](https://learn.microsoft.com/zh-cn/dotnet/api/system.indexoutofrangeexception) | 索引小于零或超出数组边界时，尝试对数组编制索引时引发。       |
| [InvalidCastException](https://learn.microsoft.com/zh-cn/dotnet/api/system.invalidcastexception) | 从基类型显式转换为接口或派生类型在运行时失败时引发。         |
| [NullReferenceException](https://learn.microsoft.com/zh-cn/dotnet/api/system.nullreferenceexception) | 尝试引用值为 [null](https://learn.microsoft.com/zh-cn/dotnet/csharp/language-reference/keywords/null) 的对象时引发。 |
| [OutOfMemoryException](https://learn.microsoft.com/zh-cn/dotnet/api/system.outofmemoryexception) | 尝试使用[新](https://learn.microsoft.com/zh-cn/dotnet/csharp/language-reference/operators/new-operator)运算符分配内存失败时引发。 此异常表示可用于公共语言运行时的内存已用尽。 |
| [OverflowException](https://learn.microsoft.com/zh-cn/dotnet/api/system.overflowexception) | `checked` 上下文中的算术运算溢出时引发。                     |
| [StackOverflowException](https://learn.microsoft.com/zh-cn/dotnet/api/system.stackoverflowexception) | 执行堆栈由于有过多挂起的方法调用而用尽时引发；通常表示非常深的递归或无限递归。 |
| [TypeInitializationException](https://learn.microsoft.com/zh-cn/dotnet/api/system.typeinitializationexception) | 静态构造函数引发异常并且没有兼容的 `catch` 子句来捕获异常时引发。 |
